2024-01-19 10:13:13,083 [WARNING]: PyNaCl is not installed, voice will NOT be supported
2024-01-19 10:13:13,084 [INFO]: logging in using static token
2024-01-19 10:13:13,904 [INFO]: Shard ID None has connected to Gateway (Session ID: 08b281df8077760a4dea2262a5f9cc46).
2024-01-19 10:13:15,912 [INFO]: 


2024-01-19 10:13:15,912 [INFO]: [93m"Avrae Integration (DoW)#5572"[32m is connected to the following guild:
    [93m"DMs Adventures"[32m (id: [93m1197704507879075860[32m)[0m
2024-01-19 10:13:15,913 [INFO]: [32mChanged bot presence.[0m
2024-01-19 10:13:15,913 [INFO]: [32mReady.[0m
2024-01-19 10:27:10,748 [WARNING]: Can't keep up, shard ID None websocket is 12.0s behind.
2024-01-19 10:28:11,341 [INFO]: Shard ID None has successfully RESUMED session 08b281df8077760a4dea2262a5f9cc46.
2024-01-19 11:16:53,913 [INFO]: Shard ID None has successfully RESUMED session 08b281df8077760a4dea2262a5f9cc46.
2024-01-19 11:43:25,183 [INFO]: Shard ID None has successfully RESUMED session 08b281df8077760a4dea2262a5f9cc46.
2024-01-19 11:45:01,672 [ERROR]: Attempting a reconnect in 1.43s
Traceback (most recent call last):
  File "/home/jacobr/miniconda3/envs/AvraeIntegration/lib/python3.12/site-packages/discord/client.py", line 659, in connect
    await self.ws.poll_event()
  File "/home/jacobr/miniconda3/envs/AvraeIntegration/lib/python3.12/site-packages/discord/gateway.py", line 646, in poll_event
    raise ConnectionClosed(self.socket, shard_id=self.shard_id, code=code) from None
discord.errors.ConnectionClosed: Shard ID None WebSocket closed with 1000
2024-01-19 11:45:23,126 [ERROR]: Attempting a reconnect in 3.60s
Traceback (most recent call last):
  File "/home/jacobr/miniconda3/envs/AvraeIntegration/lib/python3.12/site-packages/aiohttp/connector.py", line 1173, in _create_direct_connection
    hosts = await asyncio.shield(host_resolved)
            ^^^^^^^^^^^^^^^^^^^^^^^^^^^^^^^^^^^
  File "/home/jacobr/miniconda3/envs/AvraeIntegration/lib/python3.12/site-packages/aiohttp/connector.py", line 884, in _resolve_host
    addrs = await self._resolver.resolve(host, port, family=self._family)
            ^^^^^^^^^^^^^^^^^^^^^^^^^^^^^^^^^^^^^^^^^^^^^^^^^^^^^^^^^^^^^
  File "/home/jacobr/miniconda3/envs/AvraeIntegration/lib/python3.12/site-packages/aiohttp/resolver.py", line 33, in resolve
    infos = await self._loop.getaddrinfo(
            ^^^^^^^^^^^^^^^^^^^^^^^^^^^^^
  File "/home/jacobr/miniconda3/envs/AvraeIntegration/lib/python3.12/asyncio/base_events.py", line 878, in getaddrinfo
    return await self.run_in_executor(
           ^^^^^^^^^^^^^^^^^^^^^^^^^^^
  File "/home/jacobr/miniconda3/envs/AvraeIntegration/lib/python3.12/concurrent/futures/thread.py", line 58, in run
    result = self.fn(*self.args, **self.kwargs)
             ^^^^^^^^^^^^^^^^^^^^^^^^^^^^^^^^^^
  File "/home/jacobr/miniconda3/envs/AvraeIntegration/lib/python3.12/socket.py", line 963, in getaddrinfo
    for res in _socket.getaddrinfo(host, port, family, type, proto, flags):
               ^^^^^^^^^^^^^^^^^^^^^^^^^^^^^^^^^^^^^^^^^^^^^^^^^^^^^^^^^^^
socket.gaierror: [Errno -3] Temporary failure in name resolution

The above exception was the direct cause of the following exception:

Traceback (most recent call last):
  File "/home/jacobr/miniconda3/envs/AvraeIntegration/lib/python3.12/site-packages/discord/client.py", line 656, in connect
    self.ws = await asyncio.wait_for(coro, timeout=60.0)
              ^^^^^^^^^^^^^^^^^^^^^^^^^^^^^^^^^^^^^^^^^^
  File "/home/jacobr/miniconda3/envs/AvraeIntegration/lib/python3.12/asyncio/tasks.py", line 510, in wait_for
    return await fut
           ^^^^^^^^^
  File "/home/jacobr/miniconda3/envs/AvraeIntegration/lib/python3.12/site-packages/discord/gateway.py", line 372, in from_client
    socket = await client.http.ws_connect(str(url))
             ^^^^^^^^^^^^^^^^^^^^^^^^^^^^^^^^^^^^^^
  File "/home/jacobr/miniconda3/envs/AvraeIntegration/lib/python3.12/site-packages/discord/http.py", line 537, in ws_connect
    return await self.__session.ws_connect(url, **kwargs)
           ^^^^^^^^^^^^^^^^^^^^^^^^^^^^^^^^^^^^^^^^^^^^^^
  File "/home/jacobr/miniconda3/envs/AvraeIntegration/lib/python3.12/site-packages/aiohttp/client.py", line 825, in _ws_connect
    resp = await self.request(
           ^^^^^^^^^^^^^^^^^^^
  File "/home/jacobr/miniconda3/envs/AvraeIntegration/lib/python3.12/site-packages/aiohttp/client.py", line 574, in _request
    conn = await self._connector.connect(
           ^^^^^^^^^^^^^^^^^^^^^^^^^^^^^^
  File "/home/jacobr/miniconda3/envs/AvraeIntegration/lib/python3.12/site-packages/aiohttp/connector.py", line 544, in connect
    proto = await self._create_connection(req, traces, timeout)
            ^^^^^^^^^^^^^^^^^^^^^^^^^^^^^^^^^^^^^^^^^^^^^^^^^^^
  File "/home/jacobr/miniconda3/envs/AvraeIntegration/lib/python3.12/site-packages/aiohttp/connector.py", line 911, in _create_connection
    _, proto = await self._create_direct_connection(req, traces, timeout)
               ^^^^^^^^^^^^^^^^^^^^^^^^^^^^^^^^^^^^^^^^^^^^^^^^^^^^^^^^^^
  File "/home/jacobr/miniconda3/envs/AvraeIntegration/lib/python3.12/site-packages/aiohttp/connector.py", line 1187, in _create_direct_connection
    raise ClientConnectorError(req.connection_key, exc) from exc
aiohttp.client_exceptions.ClientConnectorError: Cannot connect to host gateway-us-east1-c.discord.gg:443 ssl:default [Temporary failure in name resolution]
2024-01-19 11:45:46,761 [ERROR]: Attempting a reconnect in 7.78s
Traceback (most recent call last):
  File "/home/jacobr/miniconda3/envs/AvraeIntegration/lib/python3.12/site-packages/aiohttp/connector.py", line 1173, in _create_direct_connection
    hosts = await asyncio.shield(host_resolved)
            ^^^^^^^^^^^^^^^^^^^^^^^^^^^^^^^^^^^
  File "/home/jacobr/miniconda3/envs/AvraeIntegration/lib/python3.12/site-packages/aiohttp/connector.py", line 884, in _resolve_host
    addrs = await self._resolver.resolve(host, port, family=self._family)
            ^^^^^^^^^^^^^^^^^^^^^^^^^^^^^^^^^^^^^^^^^^^^^^^^^^^^^^^^^^^^^
  File "/home/jacobr/miniconda3/envs/AvraeIntegration/lib/python3.12/site-packages/aiohttp/resolver.py", line 33, in resolve
    infos = await self._loop.getaddrinfo(
            ^^^^^^^^^^^^^^^^^^^^^^^^^^^^^
  File "/home/jacobr/miniconda3/envs/AvraeIntegration/lib/python3.12/asyncio/base_events.py", line 878, in getaddrinfo
    return await self.run_in_executor(
           ^^^^^^^^^^^^^^^^^^^^^^^^^^^
  File "/home/jacobr/miniconda3/envs/AvraeIntegration/lib/python3.12/concurrent/futures/thread.py", line 58, in run
    result = self.fn(*self.args, **self.kwargs)
             ^^^^^^^^^^^^^^^^^^^^^^^^^^^^^^^^^^
  File "/home/jacobr/miniconda3/envs/AvraeIntegration/lib/python3.12/socket.py", line 963, in getaddrinfo
    for res in _socket.getaddrinfo(host, port, family, type, proto, flags):
               ^^^^^^^^^^^^^^^^^^^^^^^^^^^^^^^^^^^^^^^^^^^^^^^^^^^^^^^^^^^
socket.gaierror: [Errno -3] Temporary failure in name resolution

The above exception was the direct cause of the following exception:

Traceback (most recent call last):
  File "/home/jacobr/miniconda3/envs/AvraeIntegration/lib/python3.12/site-packages/discord/client.py", line 656, in connect
    self.ws = await asyncio.wait_for(coro, timeout=60.0)
              ^^^^^^^^^^^^^^^^^^^^^^^^^^^^^^^^^^^^^^^^^^
  File "/home/jacobr/miniconda3/envs/AvraeIntegration/lib/python3.12/asyncio/tasks.py", line 510, in wait_for
    return await fut
           ^^^^^^^^^
  File "/home/jacobr/miniconda3/envs/AvraeIntegration/lib/python3.12/site-packages/discord/gateway.py", line 372, in from_client
    socket = await client.http.ws_connect(str(url))
             ^^^^^^^^^^^^^^^^^^^^^^^^^^^^^^^^^^^^^^
  File "/home/jacobr/miniconda3/envs/AvraeIntegration/lib/python3.12/site-packages/discord/http.py", line 537, in ws_connect
    return await self.__session.ws_connect(url, **kwargs)
           ^^^^^^^^^^^^^^^^^^^^^^^^^^^^^^^^^^^^^^^^^^^^^^
  File "/home/jacobr/miniconda3/envs/AvraeIntegration/lib/python3.12/site-packages/aiohttp/client.py", line 825, in _ws_connect
    resp = await self.request(
           ^^^^^^^^^^^^^^^^^^^
  File "/home/jacobr/miniconda3/envs/AvraeIntegration/lib/python3.12/site-packages/aiohttp/client.py", line 574, in _request
    conn = await self._connector.connect(
           ^^^^^^^^^^^^^^^^^^^^^^^^^^^^^^
  File "/home/jacobr/miniconda3/envs/AvraeIntegration/lib/python3.12/site-packages/aiohttp/connector.py", line 544, in connect
    proto = await self._create_connection(req, traces, timeout)
            ^^^^^^^^^^^^^^^^^^^^^^^^^^^^^^^^^^^^^^^^^^^^^^^^^^^
  File "/home/jacobr/miniconda3/envs/AvraeIntegration/lib/python3.12/site-packages/aiohttp/connector.py", line 911, in _create_connection
    _, proto = await self._create_direct_connection(req, traces, timeout)
               ^^^^^^^^^^^^^^^^^^^^^^^^^^^^^^^^^^^^^^^^^^^^^^^^^^^^^^^^^^
  File "/home/jacobr/miniconda3/envs/AvraeIntegration/lib/python3.12/site-packages/aiohttp/connector.py", line 1187, in _create_direct_connection
    raise ClientConnectorError(req.connection_key, exc) from exc
aiohttp.client_exceptions.ClientConnectorError: Cannot connect to host gateway-us-east1-c.discord.gg:443 ssl:default [Temporary failure in name resolution]
2024-01-19 11:46:14,577 [ERROR]: Attempting a reconnect in 0.56s
Traceback (most recent call last):
  File "/home/jacobr/miniconda3/envs/AvraeIntegration/lib/python3.12/site-packages/aiohttp/connector.py", line 1173, in _create_direct_connection
    hosts = await asyncio.shield(host_resolved)
            ^^^^^^^^^^^^^^^^^^^^^^^^^^^^^^^^^^^
  File "/home/jacobr/miniconda3/envs/AvraeIntegration/lib/python3.12/site-packages/aiohttp/connector.py", line 884, in _resolve_host
    addrs = await self._resolver.resolve(host, port, family=self._family)
            ^^^^^^^^^^^^^^^^^^^^^^^^^^^^^^^^^^^^^^^^^^^^^^^^^^^^^^^^^^^^^
  File "/home/jacobr/miniconda3/envs/AvraeIntegration/lib/python3.12/site-packages/aiohttp/resolver.py", line 33, in resolve
    infos = await self._loop.getaddrinfo(
            ^^^^^^^^^^^^^^^^^^^^^^^^^^^^^
  File "/home/jacobr/miniconda3/envs/AvraeIntegration/lib/python3.12/asyncio/base_events.py", line 878, in getaddrinfo
    return await self.run_in_executor(
           ^^^^^^^^^^^^^^^^^^^^^^^^^^^
  File "/home/jacobr/miniconda3/envs/AvraeIntegration/lib/python3.12/concurrent/futures/thread.py", line 58, in run
    result = self.fn(*self.args, **self.kwargs)
             ^^^^^^^^^^^^^^^^^^^^^^^^^^^^^^^^^^
  File "/home/jacobr/miniconda3/envs/AvraeIntegration/lib/python3.12/socket.py", line 963, in getaddrinfo
    for res in _socket.getaddrinfo(host, port, family, type, proto, flags):
               ^^^^^^^^^^^^^^^^^^^^^^^^^^^^^^^^^^^^^^^^^^^^^^^^^^^^^^^^^^^
socket.gaierror: [Errno -3] Temporary failure in name resolution

The above exception was the direct cause of the following exception:

Traceback (most recent call last):
  File "/home/jacobr/miniconda3/envs/AvraeIntegration/lib/python3.12/site-packages/discord/client.py", line 656, in connect
    self.ws = await asyncio.wait_for(coro, timeout=60.0)
              ^^^^^^^^^^^^^^^^^^^^^^^^^^^^^^^^^^^^^^^^^^
  File "/home/jacobr/miniconda3/envs/AvraeIntegration/lib/python3.12/asyncio/tasks.py", line 510, in wait_for
    return await fut
           ^^^^^^^^^
  File "/home/jacobr/miniconda3/envs/AvraeIntegration/lib/python3.12/site-packages/discord/gateway.py", line 372, in from_client
    socket = await client.http.ws_connect(str(url))
             ^^^^^^^^^^^^^^^^^^^^^^^^^^^^^^^^^^^^^^
  File "/home/jacobr/miniconda3/envs/AvraeIntegration/lib/python3.12/site-packages/discord/http.py", line 537, in ws_connect
    return await self.__session.ws_connect(url, **kwargs)
           ^^^^^^^^^^^^^^^^^^^^^^^^^^^^^^^^^^^^^^^^^^^^^^
  File "/home/jacobr/miniconda3/envs/AvraeIntegration/lib/python3.12/site-packages/aiohttp/client.py", line 825, in _ws_connect
    resp = await self.request(
           ^^^^^^^^^^^^^^^^^^^
  File "/home/jacobr/miniconda3/envs/AvraeIntegration/lib/python3.12/site-packages/aiohttp/client.py", line 574, in _request
    conn = await self._connector.connect(
           ^^^^^^^^^^^^^^^^^^^^^^^^^^^^^^
  File "/home/jacobr/miniconda3/envs/AvraeIntegration/lib/python3.12/site-packages/aiohttp/connector.py", line 544, in connect
    proto = await self._create_connection(req, traces, timeout)
            ^^^^^^^^^^^^^^^^^^^^^^^^^^^^^^^^^^^^^^^^^^^^^^^^^^^
  File "/home/jacobr/miniconda3/envs/AvraeIntegration/lib/python3.12/site-packages/aiohttp/connector.py", line 911, in _create_connection
    _, proto = await self._create_direct_connection(req, traces, timeout)
               ^^^^^^^^^^^^^^^^^^^^^^^^^^^^^^^^^^^^^^^^^^^^^^^^^^^^^^^^^^
  File "/home/jacobr/miniconda3/envs/AvraeIntegration/lib/python3.12/site-packages/aiohttp/connector.py", line 1187, in _create_direct_connection
    raise ClientConnectorError(req.connection_key, exc) from exc
aiohttp.client_exceptions.ClientConnectorError: Cannot connect to host gateway-us-east1-c.discord.gg:443 ssl:default [Temporary failure in name resolution]
2024-01-19 11:47:15,180 [ERROR]: Attempting a reconnect in 2.52s
Traceback (most recent call last):
  File "/home/jacobr/miniconda3/envs/AvraeIntegration/lib/python3.12/asyncio/tasks.py", line 510, in wait_for
    return await fut
           ^^^^^^^^^
  File "/home/jacobr/miniconda3/envs/AvraeIntegration/lib/python3.12/site-packages/discord/gateway.py", line 372, in from_client
    socket = await client.http.ws_connect(str(url))
             ^^^^^^^^^^^^^^^^^^^^^^^^^^^^^^^^^^^^^^
  File "/home/jacobr/miniconda3/envs/AvraeIntegration/lib/python3.12/site-packages/discord/http.py", line 537, in ws_connect
    return await self.__session.ws_connect(url, **kwargs)
           ^^^^^^^^^^^^^^^^^^^^^^^^^^^^^^^^^^^^^^^^^^^^^^
  File "/home/jacobr/miniconda3/envs/AvraeIntegration/lib/python3.12/site-packages/aiohttp/client.py", line 825, in _ws_connect
    resp = await self.request(
           ^^^^^^^^^^^^^^^^^^^
  File "/home/jacobr/miniconda3/envs/AvraeIntegration/lib/python3.12/site-packages/aiohttp/client.py", line 574, in _request
    conn = await self._connector.connect(
           ^^^^^^^^^^^^^^^^^^^^^^^^^^^^^^
  File "/home/jacobr/miniconda3/envs/AvraeIntegration/lib/python3.12/site-packages/aiohttp/connector.py", line 544, in connect
    proto = await self._create_connection(req, traces, timeout)
            ^^^^^^^^^^^^^^^^^^^^^^^^^^^^^^^^^^^^^^^^^^^^^^^^^^^
  File "/home/jacobr/miniconda3/envs/AvraeIntegration/lib/python3.12/site-packages/aiohttp/connector.py", line 911, in _create_connection
    _, proto = await self._create_direct_connection(req, traces, timeout)
               ^^^^^^^^^^^^^^^^^^^^^^^^^^^^^^^^^^^^^^^^^^^^^^^^^^^^^^^^^^
  File "/home/jacobr/miniconda3/envs/AvraeIntegration/lib/python3.12/site-packages/aiohttp/connector.py", line 1204, in _create_direct_connection
    transp, proto = await self._wrap_create_connection(
                    ^^^^^^^^^^^^^^^^^^^^^^^^^^^^^^^^^^^
  File "/home/jacobr/miniconda3/envs/AvraeIntegration/lib/python3.12/site-packages/aiohttp/connector.py", line 992, in _wrap_create_connection
    return await self._loop.create_connection(*args, **kwargs)
           ^^^^^^^^^^^^^^^^^^^^^^^^^^^^^^^^^^^^^^^^^^^^^^^^^^^
  File "/home/jacobr/miniconda3/envs/AvraeIntegration/lib/python3.12/asyncio/base_events.py", line 1126, in create_connection
    transport, protocol = await self._create_connection_transport(
                          ^^^^^^^^^^^^^^^^^^^^^^^^^^^^^^^^^^^^^^^^
  File "/home/jacobr/miniconda3/envs/AvraeIntegration/lib/python3.12/asyncio/base_events.py", line 1159, in _create_connection_transport
    await waiter
asyncio.exceptions.CancelledError

The above exception was the direct cause of the following exception:

Traceback (most recent call last):
  File "/home/jacobr/miniconda3/envs/AvraeIntegration/lib/python3.12/site-packages/discord/client.py", line 656, in connect
    self.ws = await asyncio.wait_for(coro, timeout=60.0)
              ^^^^^^^^^^^^^^^^^^^^^^^^^^^^^^^^^^^^^^^^^^
  File "/home/jacobr/miniconda3/envs/AvraeIntegration/lib/python3.12/asyncio/tasks.py", line 509, in wait_for
    async with timeouts.timeout(timeout):
  File "/home/jacobr/miniconda3/envs/AvraeIntegration/lib/python3.12/asyncio/timeouts.py", line 111, in __aexit__
    raise TimeoutError from exc_val
TimeoutError
2024-01-19 11:47:37,724 [ERROR]: Attempting a reconnect in 14.98s
Traceback (most recent call last):
  File "/home/jacobr/miniconda3/envs/AvraeIntegration/lib/python3.12/site-packages/aiohttp/connector.py", line 1173, in _create_direct_connection
    hosts = await asyncio.shield(host_resolved)
            ^^^^^^^^^^^^^^^^^^^^^^^^^^^^^^^^^^^
  File "/home/jacobr/miniconda3/envs/AvraeIntegration/lib/python3.12/site-packages/aiohttp/connector.py", line 884, in _resolve_host
    addrs = await self._resolver.resolve(host, port, family=self._family)
            ^^^^^^^^^^^^^^^^^^^^^^^^^^^^^^^^^^^^^^^^^^^^^^^^^^^^^^^^^^^^^
  File "/home/jacobr/miniconda3/envs/AvraeIntegration/lib/python3.12/site-packages/aiohttp/resolver.py", line 33, in resolve
    infos = await self._loop.getaddrinfo(
            ^^^^^^^^^^^^^^^^^^^^^^^^^^^^^
  File "/home/jacobr/miniconda3/envs/AvraeIntegration/lib/python3.12/asyncio/base_events.py", line 878, in getaddrinfo
    return await self.run_in_executor(
           ^^^^^^^^^^^^^^^^^^^^^^^^^^^
  File "/home/jacobr/miniconda3/envs/AvraeIntegration/lib/python3.12/concurrent/futures/thread.py", line 58, in run
    result = self.fn(*self.args, **self.kwargs)
             ^^^^^^^^^^^^^^^^^^^^^^^^^^^^^^^^^^
  File "/home/jacobr/miniconda3/envs/AvraeIntegration/lib/python3.12/socket.py", line 963, in getaddrinfo
    for res in _socket.getaddrinfo(host, port, family, type, proto, flags):
               ^^^^^^^^^^^^^^^^^^^^^^^^^^^^^^^^^^^^^^^^^^^^^^^^^^^^^^^^^^^
socket.gaierror: [Errno -3] Temporary failure in name resolution

The above exception was the direct cause of the following exception:

Traceback (most recent call last):
  File "/home/jacobr/miniconda3/envs/AvraeIntegration/lib/python3.12/site-packages/discord/client.py", line 656, in connect
    self.ws = await asyncio.wait_for(coro, timeout=60.0)
              ^^^^^^^^^^^^^^^^^^^^^^^^^^^^^^^^^^^^^^^^^^
  File "/home/jacobr/miniconda3/envs/AvraeIntegration/lib/python3.12/asyncio/tasks.py", line 510, in wait_for
    return await fut
           ^^^^^^^^^
  File "/home/jacobr/miniconda3/envs/AvraeIntegration/lib/python3.12/site-packages/discord/gateway.py", line 372, in from_client
    socket = await client.http.ws_connect(str(url))
             ^^^^^^^^^^^^^^^^^^^^^^^^^^^^^^^^^^^^^^
  File "/home/jacobr/miniconda3/envs/AvraeIntegration/lib/python3.12/site-packages/discord/http.py", line 537, in ws_connect
    return await self.__session.ws_connect(url, **kwargs)
           ^^^^^^^^^^^^^^^^^^^^^^^^^^^^^^^^^^^^^^^^^^^^^^
  File "/home/jacobr/miniconda3/envs/AvraeIntegration/lib/python3.12/site-packages/aiohttp/client.py", line 825, in _ws_connect
    resp = await self.request(
           ^^^^^^^^^^^^^^^^^^^
  File "/home/jacobr/miniconda3/envs/AvraeIntegration/lib/python3.12/site-packages/aiohttp/client.py", line 574, in _request
    conn = await self._connector.connect(
           ^^^^^^^^^^^^^^^^^^^^^^^^^^^^^^
  File "/home/jacobr/miniconda3/envs/AvraeIntegration/lib/python3.12/site-packages/aiohttp/connector.py", line 544, in connect
    proto = await self._create_connection(req, traces, timeout)
            ^^^^^^^^^^^^^^^^^^^^^^^^^^^^^^^^^^^^^^^^^^^^^^^^^^^
  File "/home/jacobr/miniconda3/envs/AvraeIntegration/lib/python3.12/site-packages/aiohttp/connector.py", line 911, in _create_connection
    _, proto = await self._create_direct_connection(req, traces, timeout)
               ^^^^^^^^^^^^^^^^^^^^^^^^^^^^^^^^^^^^^^^^^^^^^^^^^^^^^^^^^^
  File "/home/jacobr/miniconda3/envs/AvraeIntegration/lib/python3.12/site-packages/aiohttp/connector.py", line 1187, in _create_direct_connection
    raise ClientConnectorError(req.connection_key, exc) from exc
aiohttp.client_exceptions.ClientConnectorError: Cannot connect to host gateway-us-east1-c.discord.gg:443 ssl:default [Temporary failure in name resolution]
2024-01-19 11:48:12,741 [ERROR]: Attempting a reconnect in 87.57s
Traceback (most recent call last):
  File "/home/jacobr/miniconda3/envs/AvraeIntegration/lib/python3.12/site-packages/aiohttp/connector.py", line 1173, in _create_direct_connection
    hosts = await asyncio.shield(host_resolved)
            ^^^^^^^^^^^^^^^^^^^^^^^^^^^^^^^^^^^
  File "/home/jacobr/miniconda3/envs/AvraeIntegration/lib/python3.12/site-packages/aiohttp/connector.py", line 884, in _resolve_host
    addrs = await self._resolver.resolve(host, port, family=self._family)
            ^^^^^^^^^^^^^^^^^^^^^^^^^^^^^^^^^^^^^^^^^^^^^^^^^^^^^^^^^^^^^
  File "/home/jacobr/miniconda3/envs/AvraeIntegration/lib/python3.12/site-packages/aiohttp/resolver.py", line 33, in resolve
    infos = await self._loop.getaddrinfo(
            ^^^^^^^^^^^^^^^^^^^^^^^^^^^^^
  File "/home/jacobr/miniconda3/envs/AvraeIntegration/lib/python3.12/asyncio/base_events.py", line 878, in getaddrinfo
    return await self.run_in_executor(
           ^^^^^^^^^^^^^^^^^^^^^^^^^^^
  File "/home/jacobr/miniconda3/envs/AvraeIntegration/lib/python3.12/concurrent/futures/thread.py", line 58, in run
    result = self.fn(*self.args, **self.kwargs)
             ^^^^^^^^^^^^^^^^^^^^^^^^^^^^^^^^^^
  File "/home/jacobr/miniconda3/envs/AvraeIntegration/lib/python3.12/socket.py", line 963, in getaddrinfo
    for res in _socket.getaddrinfo(host, port, family, type, proto, flags):
               ^^^^^^^^^^^^^^^^^^^^^^^^^^^^^^^^^^^^^^^^^^^^^^^^^^^^^^^^^^^
socket.gaierror: [Errno -3] Temporary failure in name resolution

The above exception was the direct cause of the following exception:

Traceback (most recent call last):
  File "/home/jacobr/miniconda3/envs/AvraeIntegration/lib/python3.12/site-packages/discord/client.py", line 656, in connect
    self.ws = await asyncio.wait_for(coro, timeout=60.0)
              ^^^^^^^^^^^^^^^^^^^^^^^^^^^^^^^^^^^^^^^^^^
  File "/home/jacobr/miniconda3/envs/AvraeIntegration/lib/python3.12/asyncio/tasks.py", line 510, in wait_for
    return await fut
           ^^^^^^^^^
  File "/home/jacobr/miniconda3/envs/AvraeIntegration/lib/python3.12/site-packages/discord/gateway.py", line 372, in from_client
    socket = await client.http.ws_connect(str(url))
             ^^^^^^^^^^^^^^^^^^^^^^^^^^^^^^^^^^^^^^
  File "/home/jacobr/miniconda3/envs/AvraeIntegration/lib/python3.12/site-packages/discord/http.py", line 537, in ws_connect
    return await self.__session.ws_connect(url, **kwargs)
           ^^^^^^^^^^^^^^^^^^^^^^^^^^^^^^^^^^^^^^^^^^^^^^
  File "/home/jacobr/miniconda3/envs/AvraeIntegration/lib/python3.12/site-packages/aiohttp/client.py", line 825, in _ws_connect
    resp = await self.request(
           ^^^^^^^^^^^^^^^^^^^
  File "/home/jacobr/miniconda3/envs/AvraeIntegration/lib/python3.12/site-packages/aiohttp/client.py", line 574, in _request
    conn = await self._connector.connect(
           ^^^^^^^^^^^^^^^^^^^^^^^^^^^^^^
  File "/home/jacobr/miniconda3/envs/AvraeIntegration/lib/python3.12/site-packages/aiohttp/connector.py", line 544, in connect
    proto = await self._create_connection(req, traces, timeout)
            ^^^^^^^^^^^^^^^^^^^^^^^^^^^^^^^^^^^^^^^^^^^^^^^^^^^
  File "/home/jacobr/miniconda3/envs/AvraeIntegration/lib/python3.12/site-packages/aiohttp/connector.py", line 911, in _create_connection
    _, proto = await self._create_direct_connection(req, traces, timeout)
               ^^^^^^^^^^^^^^^^^^^^^^^^^^^^^^^^^^^^^^^^^^^^^^^^^^^^^^^^^^
  File "/home/jacobr/miniconda3/envs/AvraeIntegration/lib/python3.12/site-packages/aiohttp/connector.py", line 1187, in _create_direct_connection
    raise ClientConnectorError(req.connection_key, exc) from exc
aiohttp.client_exceptions.ClientConnectorError: Cannot connect to host gateway-us-east1-c.discord.gg:443 ssl:default [Temporary failure in name resolution]
2024-01-19 11:50:00,413 [ERROR]: Attempting a reconnect in 60.38s
Traceback (most recent call last):
  File "/home/jacobr/miniconda3/envs/AvraeIntegration/lib/python3.12/site-packages/aiohttp/connector.py", line 1173, in _create_direct_connection
    hosts = await asyncio.shield(host_resolved)
            ^^^^^^^^^^^^^^^^^^^^^^^^^^^^^^^^^^^
  File "/home/jacobr/miniconda3/envs/AvraeIntegration/lib/python3.12/site-packages/aiohttp/connector.py", line 884, in _resolve_host
    addrs = await self._resolver.resolve(host, port, family=self._family)
            ^^^^^^^^^^^^^^^^^^^^^^^^^^^^^^^^^^^^^^^^^^^^^^^^^^^^^^^^^^^^^
  File "/home/jacobr/miniconda3/envs/AvraeIntegration/lib/python3.12/site-packages/aiohttp/resolver.py", line 33, in resolve
    infos = await self._loop.getaddrinfo(
            ^^^^^^^^^^^^^^^^^^^^^^^^^^^^^
  File "/home/jacobr/miniconda3/envs/AvraeIntegration/lib/python3.12/asyncio/base_events.py", line 878, in getaddrinfo
    return await self.run_in_executor(
           ^^^^^^^^^^^^^^^^^^^^^^^^^^^
  File "/home/jacobr/miniconda3/envs/AvraeIntegration/lib/python3.12/concurrent/futures/thread.py", line 58, in run
    result = self.fn(*self.args, **self.kwargs)
             ^^^^^^^^^^^^^^^^^^^^^^^^^^^^^^^^^^
  File "/home/jacobr/miniconda3/envs/AvraeIntegration/lib/python3.12/socket.py", line 963, in getaddrinfo
    for res in _socket.getaddrinfo(host, port, family, type, proto, flags):
               ^^^^^^^^^^^^^^^^^^^^^^^^^^^^^^^^^^^^^^^^^^^^^^^^^^^^^^^^^^^
socket.gaierror: [Errno -3] Temporary failure in name resolution

The above exception was the direct cause of the following exception:

Traceback (most recent call last):
  File "/home/jacobr/miniconda3/envs/AvraeIntegration/lib/python3.12/site-packages/discord/client.py", line 656, in connect
    self.ws = await asyncio.wait_for(coro, timeout=60.0)
              ^^^^^^^^^^^^^^^^^^^^^^^^^^^^^^^^^^^^^^^^^^
  File "/home/jacobr/miniconda3/envs/AvraeIntegration/lib/python3.12/asyncio/tasks.py", line 510, in wait_for
    return await fut
           ^^^^^^^^^
  File "/home/jacobr/miniconda3/envs/AvraeIntegration/lib/python3.12/site-packages/discord/gateway.py", line 372, in from_client
    socket = await client.http.ws_connect(str(url))
             ^^^^^^^^^^^^^^^^^^^^^^^^^^^^^^^^^^^^^^
  File "/home/jacobr/miniconda3/envs/AvraeIntegration/lib/python3.12/site-packages/discord/http.py", line 537, in ws_connect
    return await self.__session.ws_connect(url, **kwargs)
           ^^^^^^^^^^^^^^^^^^^^^^^^^^^^^^^^^^^^^^^^^^^^^^
  File "/home/jacobr/miniconda3/envs/AvraeIntegration/lib/python3.12/site-packages/aiohttp/client.py", line 825, in _ws_connect
    resp = await self.request(
           ^^^^^^^^^^^^^^^^^^^
  File "/home/jacobr/miniconda3/envs/AvraeIntegration/lib/python3.12/site-packages/aiohttp/client.py", line 574, in _request
    conn = await self._connector.connect(
           ^^^^^^^^^^^^^^^^^^^^^^^^^^^^^^
  File "/home/jacobr/miniconda3/envs/AvraeIntegration/lib/python3.12/site-packages/aiohttp/connector.py", line 544, in connect
    proto = await self._create_connection(req, traces, timeout)
            ^^^^^^^^^^^^^^^^^^^^^^^^^^^^^^^^^^^^^^^^^^^^^^^^^^^
  File "/home/jacobr/miniconda3/envs/AvraeIntegration/lib/python3.12/site-packages/aiohttp/connector.py", line 911, in _create_connection
    _, proto = await self._create_direct_connection(req, traces, timeout)
               ^^^^^^^^^^^^^^^^^^^^^^^^^^^^^^^^^^^^^^^^^^^^^^^^^^^^^^^^^^
  File "/home/jacobr/miniconda3/envs/AvraeIntegration/lib/python3.12/site-packages/aiohttp/connector.py", line 1187, in _create_direct_connection
    raise ClientConnectorError(req.connection_key, exc) from exc
aiohttp.client_exceptions.ClientConnectorError: Cannot connect to host gateway-us-east1-c.discord.gg:443 ssl:default [Temporary failure in name resolution]
2024-01-19 11:51:04,422 [INFO]: Shard ID None session has been invalidated.
2024-01-19 11:51:41,902 [INFO]: Shard ID None has connected to Gateway (Session ID: 6bc6ee3a4f04a48d59da9451b7b146fd).
2024-01-19 11:51:43,944 [INFO]: 


2024-01-19 11:51:43,945 [INFO]: [93m"Avrae Integration (DoW)#5572"[32m is connected to the following guild:
    [93m"DMs Adventures"[32m (id: [93m1197704507879075860[32m)[0m
2024-01-19 11:51:43,948 [INFO]: [32mChanged bot presence.[0m
2024-01-19 11:51:43,948 [INFO]: [32mReady.[0m
2024-01-19 11:52:39,639 [WARNING]: Can't keep up, shard ID None websocket is 12.4s behind.
2024-01-19 11:54:45,984 [ERROR]: Attempting a reconnect in 481.45s
Traceback (most recent call last):
  File "/home/jacobr/miniconda3/envs/AvraeIntegration/lib/python3.12/site-packages/discord/client.py", line 659, in connect
    await self.ws.poll_event()
  File "/home/jacobr/miniconda3/envs/AvraeIntegration/lib/python3.12/site-packages/discord/gateway.py", line 646, in poll_event
    raise ConnectionClosed(self.socket, shard_id=self.shard_id, code=code) from None
discord.errors.ConnectionClosed: Shard ID None WebSocket closed with 1000
2024-01-19 12:02:47,926 [INFO]: Shard ID None session has been invalidated.
2024-01-19 12:02:53,433 [INFO]: Shard ID None has connected to Gateway (Session ID: 48138d1934c432f37c0213d3d8fdb241).
2024-01-19 12:02:55,440 [INFO]: 


2024-01-19 12:02:55,441 [INFO]: [93m"Avrae Integration (DoW)#5572"[32m is connected to the following guild:
    [93m"DMs Adventures"[32m (id: [93m1197704507879075860[32m)[0m
2024-01-19 12:02:55,441 [INFO]: [32mChanged bot presence.[0m
2024-01-19 12:02:55,441 [INFO]: [32mReady.[0m
2024-01-19 12:19:38,036 [WARNING]: Can't keep up, shard ID None websocket is 19.8s behind.
2024-01-19 12:43:41,274 [INFO]: Shard ID None has successfully RESUMED session 48138d1934c432f37c0213d3d8fdb241.
2024-01-19 12:45:41,447 [INFO]: [93mdiabolicalgolem [0missued: [36mdnd[0m
2024-01-19 12:45:41,814 [INFO]: [32mDeleted issuing command.[0m
2024-01-19 12:45:41,814 [INFO]: [32mGrabbed author's name:
    [93mDiabolicalGolem[0m
2024-01-19 12:45:41,814 [INFO]: [32mFound channel path:
    [93mgameplay[0m
2024-01-19 12:45:42,083 [INFO]: [32mSent anchoring message:
    [93mDiabolicalGolem's Thread:[0m
2024-01-19 12:45:42,462 [INFO]: [32mSet thread title:
    [93mDiabolicalGolem's Thread:[0m
2024-01-19 12:45:42,681 [INFO]: [32mSent welcome text.[0m
2024-01-19 12:45:51,304 [INFO]: [93mdiabolicalgolem [0missued: [36mdndend[0m
2024-01-19 12:45:51,604 [INFO]: [32mDeleted issuing command.[0m
2024-01-19 12:45:51,993 [INFO]: [32mGrabbed anchor message source:
    [0mchannel_id:[93m1197872302939971644[0m, mmessage_id:1197990286647894017[0m
2024-01-19 12:45:52,305 [INFO]: [32mDeleted thread.[0m
2024-01-19 12:45:52,524 [INFO]: [32mDeleted anchor message.[0m
2024-01-19 12:45:56,480 [INFO]: [93mdiabolicalgolem [0missued: [36mdndend[0m
2024-01-19 12:45:56,726 [INFO]: [32mDeleted issuing command.[0m
2024-01-19 12:45:57,146 [INFO]: [32mGrabbed anchor message source:
    [0mchannel_id:[93m1197872302939971644[0m, mmessage_id:1197946281977462804[0m
2024-01-19 12:45:57,620 [INFO]: [32mDeleted thread.[0m
2024-01-19 12:45:57,809 [INFO]: [32mDeleted anchor message.[0m
2024-01-19 12:46:03,129 [INFO]: [93mdiabolicalgolem [0missued: [36mdndend[0m
2024-01-19 12:46:03,362 [INFO]: [32mDeleted issuing command.[0m
2024-01-19 12:46:03,753 [INFO]: [32mGrabbed anchor message source:
    [0mchannel_id:[93m1197872302939971644[0m, mmessage_id:1197946277107863644[0m
2024-01-19 12:46:04,110 [INFO]: [32mDeleted thread.[0m
2024-01-19 12:46:04,358 [INFO]: [32mDeleted anchor message.[0m
2024-01-19 12:46:21,332 [INFO]: [93mdiabolicalgolem [0missued: [36mdndend[0m
2024-01-19 12:46:21,775 [INFO]: [32mDeleted issuing command.[0m
2024-01-19 12:46:22,306 [INFO]: [32mGrabbed anchor message source:
    [0mchannel_id:[93m1197872302939971644[0m, mmessage_id:1197946272007589969[0m
2024-01-19 12:46:22,623 [INFO]: [32mDeleted thread.[0m
2024-01-19 12:46:22,843 [INFO]: [32mDeleted anchor message.[0m
2024-01-19 12:46:28,752 [INFO]: [93mdiabolicalgolem [0missued: [36mdndend[0m
2024-01-19 12:46:29,106 [INFO]: [32mDeleted issuing command.[0m
2024-01-19 12:46:29,596 [INFO]: [32mGrabbed anchor message source:
    [0mchannel_id:[93m1197872302939971644[0m, mmessage_id:1197946265309286551[0m
2024-01-19 12:46:29,884 [INFO]: [32mDeleted thread.[0m
2024-01-19 12:46:30,259 [INFO]: [32mDeleted anchor message.[0m
2024-01-19 12:46:43,446 [INFO]: [93mdiabolicalgolem [0missued: [36mdnd[0m
2024-01-19 12:46:43,688 [INFO]: [32mDeleted issuing command.[0m
2024-01-19 12:46:43,688 [INFO]: [32mGrabbed author's name:
    [93mDiabolicalGolem[0m
2024-01-19 12:46:43,688 [INFO]: [32mFound channel path:
    [93mgameplay[0m
2024-01-19 12:46:43,934 [INFO]: [32mSent anchoring message:
    [93mDiabolicalGolem's Thread:[0m
2024-01-19 12:46:44,264 [INFO]: [32mSet thread title:
    [93mDiabolicalGolem's Thread:[0m
2024-01-19 12:46:44,466 [INFO]: [32mSent welcome text.[0m
2024-01-19 12:46:54,357 [INFO]: [93mdiabolicalgolem [0missued: [36mdndren[0m
2024-01-19 12:46:54,603 [INFO]: [32mDeleted issuing command.[0m
2024-01-19 12:46:54,603 [INFO]: [32mJoined new_name:
    [0mnew_name: "[93mtest[0m"
2024-01-19 12:46:55,445 [INFO]: [32mChanged thread name to new_name[0m
2024-01-19 12:46:59,903 [INFO]: [32mServed success message.[0m
